<?xml version="1.0" encoding="UTF-8"?>
<!-- Generated by org.testng.reporters.JUnitReportReporter -->
<testsuite hostname="YOGI" name="com.practice1.ReadExcelTestNg" tests="3" failures="3" timestamp="4 Jun 2018 11:14:36 GMT" time="110.480" errors="0">
  <testcase name="Login" time="35.165" classname="com.practice1.ReadExcelTestNg">
    <failure type="java.lang.AssertionError" message="expected [https://www.facebook.com/login.php?login_attempt=1&amp;lwv=110] but found [https://www.facebook.com]">
      <![CDATA[java.lang.AssertionError: expected [https://www.facebook.com/login.php?login_attempt=1&lwv=110] but found [https://www.facebook.com]
	at org.testng.Assert.fail(Assert.java:94)
	at org.testng.Assert.failNotEquals(Assert.java:496)
	at org.testng.Assert.assertEquals(Assert.java:125)
	at org.testng.Assert.assertEquals(Assert.java:178)
	at org.testng.Assert.assertEquals(Assert.java:188)
	at com.practice1.ReadExcelTestNg.Login(ReadExcelTestNg.java:27)
	at sun.reflect.NativeMethodAccessorImpl.invoke0(Native Method)
	at sun.reflect.NativeMethodAccessorImpl.invoke(Unknown Source)
	at sun.reflect.DelegatingMethodAccessorImpl.invoke(Unknown Source)
	at java.lang.reflect.Method.invoke(Unknown Source)
	at org.testng.internal.MethodInvocationHelper.invokeMethod(MethodInvocationHelper.java:85)
	at org.testng.internal.Invoker.invokeMethod(Invoker.java:639)
	at org.testng.internal.Invoker.invokeTestMethod(Invoker.java:816)
	at org.testng.internal.Invoker.invokeTestMethods(Invoker.java:1124)
	at org.testng.internal.TestMethodWorker.invokeTestMethods(TestMethodWorker.java:125)
	at org.testng.internal.TestMethodWorker.run(TestMethodWorker.java:108)
	at org.testng.TestRunner.privateRun(TestRunner.java:774)
	at org.testng.TestRunner.run(TestRunner.java:624)
	at org.testng.SuiteRunner.runTest(SuiteRunner.java:359)
	at org.testng.SuiteRunner.runSequentially(SuiteRunner.java:354)
	at org.testng.SuiteRunner.privateRun(SuiteRunner.java:312)
	at org.testng.SuiteRunner.run(SuiteRunner.java:261)
	at org.testng.SuiteRunnerWorker.runSuite(SuiteRunnerWorker.java:52)
	at org.testng.SuiteRunnerWorker.run(SuiteRunnerWorker.java:86)
	at org.testng.TestNG.runSuitesSequentially(TestNG.java:1215)
	at org.testng.TestNG.runSuitesLocally(TestNG.java:1140)
	at org.testng.TestNG.run(TestNG.java:1048)
	at org.testng.remote.AbstractRemoteTestNG.run(AbstractRemoteTestNG.java:114)
	at org.testng.remote.RemoteTestNG.initAndRun(RemoteTestNG.java:251)
	at org.testng.remote.RemoteTestNG.main(RemoteTestNG.java:77)
]]>
    </failure>
  </testcase> <!-- Login -->
  <testcase name="Login" time="40.023" classname="com.practice1.ReadExcelTestNg">
    <failure type="java.lang.AssertionError" message="expected [https://www.facebook.com/login.php?login_attempt=1&amp;lwv=110] but found [https://www.facebook.com]">
      <![CDATA[java.lang.AssertionError: expected [https://www.facebook.com/login.php?login_attempt=1&lwv=110] but found [https://www.facebook.com]
	at org.testng.Assert.fail(Assert.java:94)
	at org.testng.Assert.failNotEquals(Assert.java:496)
	at org.testng.Assert.assertEquals(Assert.java:125)
	at org.testng.Assert.assertEquals(Assert.java:178)
	at org.testng.Assert.assertEquals(Assert.java:188)
	at com.practice1.ReadExcelTestNg.Login(ReadExcelTestNg.java:27)
	at sun.reflect.NativeMethodAccessorImpl.invoke0(Native Method)
	at sun.reflect.NativeMethodAccessorImpl.invoke(Unknown Source)
	at sun.reflect.DelegatingMethodAccessorImpl.invoke(Unknown Source)
	at java.lang.reflect.Method.invoke(Unknown Source)
	at org.testng.internal.MethodInvocationHelper.invokeMethod(MethodInvocationHelper.java:85)
	at org.testng.internal.Invoker.invokeMethod(Invoker.java:639)
	at org.testng.internal.Invoker.invokeTestMethod(Invoker.java:816)
	at org.testng.internal.Invoker.invokeTestMethods(Invoker.java:1124)
	at org.testng.internal.TestMethodWorker.invokeTestMethods(TestMethodWorker.java:125)
	at org.testng.internal.TestMethodWorker.run(TestMethodWorker.java:108)
	at org.testng.TestRunner.privateRun(TestRunner.java:774)
	at org.testng.TestRunner.run(TestRunner.java:624)
	at org.testng.SuiteRunner.runTest(SuiteRunner.java:359)
	at org.testng.SuiteRunner.runSequentially(SuiteRunner.java:354)
	at org.testng.SuiteRunner.privateRun(SuiteRunner.java:312)
	at org.testng.SuiteRunner.run(SuiteRunner.java:261)
	at org.testng.SuiteRunnerWorker.runSuite(SuiteRunnerWorker.java:52)
	at org.testng.SuiteRunnerWorker.run(SuiteRunnerWorker.java:86)
	at org.testng.TestNG.runSuitesSequentially(TestNG.java:1215)
	at org.testng.TestNG.runSuitesLocally(TestNG.java:1140)
	at org.testng.TestNG.run(TestNG.java:1048)
	at org.testng.remote.AbstractRemoteTestNG.run(AbstractRemoteTestNG.java:114)
	at org.testng.remote.RemoteTestNG.initAndRun(RemoteTestNG.java:251)
	at org.testng.remote.RemoteTestNG.main(RemoteTestNG.java:77)
]]>
    </failure>
  </testcase> <!-- Login -->
  <testcase name="Login" time="35.292" classname="com.practice1.ReadExcelTestNg">
    <failure type="java.lang.AssertionError" message="expected [https://www.facebook.com/login.php?login_attempt=1&amp;lwv=110] but found [https://www.facebook.com]">
      <![CDATA[java.lang.AssertionError: expected [https://www.facebook.com/login.php?login_attempt=1&lwv=110] but found [https://www.facebook.com]
	at org.testng.Assert.fail(Assert.java:94)
	at org.testng.Assert.failNotEquals(Assert.java:496)
	at org.testng.Assert.assertEquals(Assert.java:125)
	at org.testng.Assert.assertEquals(Assert.java:178)
	at org.testng.Assert.assertEquals(Assert.java:188)
	at com.practice1.ReadExcelTestNg.Login(ReadExcelTestNg.java:27)
	at sun.reflect.NativeMethodAccessorImpl.invoke0(Native Method)
	at sun.reflect.NativeMethodAccessorImpl.invoke(Unknown Source)
	at sun.reflect.DelegatingMethodAccessorImpl.invoke(Unknown Source)
	at java.lang.reflect.Method.invoke(Unknown Source)
	at org.testng.internal.MethodInvocationHelper.invokeMethod(MethodInvocationHelper.java:85)
	at org.testng.internal.Invoker.invokeMethod(Invoker.java:639)
	at org.testng.internal.Invoker.invokeTestMethod(Invoker.java:816)
	at org.testng.internal.Invoker.invokeTestMethods(Invoker.java:1124)
	at org.testng.internal.TestMethodWorker.invokeTestMethods(TestMethodWorker.java:125)
	at org.testng.internal.TestMethodWorker.run(TestMethodWorker.java:108)
	at org.testng.TestRunner.privateRun(TestRunner.java:774)
	at org.testng.TestRunner.run(TestRunner.java:624)
	at org.testng.SuiteRunner.runTest(SuiteRunner.java:359)
	at org.testng.SuiteRunner.runSequentially(SuiteRunner.java:354)
	at org.testng.SuiteRunner.privateRun(SuiteRunner.java:312)
	at org.testng.SuiteRunner.run(SuiteRunner.java:261)
	at org.testng.SuiteRunnerWorker.runSuite(SuiteRunnerWorker.java:52)
	at org.testng.SuiteRunnerWorker.run(SuiteRunnerWorker.java:86)
	at org.testng.TestNG.runSuitesSequentially(TestNG.java:1215)
	at org.testng.TestNG.runSuitesLocally(TestNG.java:1140)
	at org.testng.TestNG.run(TestNG.java:1048)
	at org.testng.remote.AbstractRemoteTestNG.run(AbstractRemoteTestNG.java:114)
	at org.testng.remote.RemoteTestNG.initAndRun(RemoteTestNG.java:251)
	at org.testng.remote.RemoteTestNG.main(RemoteTestNG.java:77)
]]>
    </failure>
  </testcase> <!-- Login -->
</testsuite> <!-- com.practice1.ReadExcelTestNg -->
